[2023-09-06 17:25:21,298] ERROR log_exception() L1449 Exception on /tutores [GET] - call_trace=/Users/tairik/PycharmProjects/mvp-tairik/venv/lib/python3.9/site-packages/flask/app.py L1449
Traceback (most recent call last):
  File "/Users/tairik/PycharmProjects/mvp-tairik/venv/lib/python3.9/site-packages/flask/app.py", line 2073, in wsgi_app
    response = self.full_dispatch_request()
  File "/Users/tairik/PycharmProjects/mvp-tairik/venv/lib/python3.9/site-packages/flask/app.py", line 1519, in full_dispatch_request
    rv = self.handle_user_exception(e)
  File "/Users/tairik/PycharmProjects/mvp-tairik/venv/lib/python3.9/site-packages/flask_cors/extension.py", line 165, in wrapped_function
    return cors_after_request(app.make_response(f(*args, **kwargs)))
  File "/Users/tairik/PycharmProjects/mvp-tairik/venv/lib/python3.9/site-packages/flask/app.py", line 1517, in full_dispatch_request
    rv = self.dispatch_request()
  File "/Users/tairik/PycharmProjects/mvp-tairik/venv/lib/python3.9/site-packages/flask/app.py", line 1503, in dispatch_request
    return self.ensure_sync(self.view_functions[rule.endpoint])(**req.view_args)
  File "/Users/tairik/PycharmProjects/mvp-tairik/venv/lib/python3.9/site-packages/flask_openapi3/scaffold.py", line 109, in wrapper
    resp = _do_wrapper(
  File "/Users/tairik/PycharmProjects/mvp-tairik/venv/lib/python3.9/site-packages/flask_openapi3/do_wrapper.py", line 135, in _do_wrapper
    response = func(**request_kwargs)
  File "/Users/tairik/PycharmProjects/mvp-tairik/rest_api_tutores/app.py", line 132, in get_tutores
    print(results.is_valid_format.value)
AttributeError: 'bytes' object has no attribute 'is_valid_format'
[2023-09-06 17:25:21,318] INFO _log() L224  127.0.0.1 - - [06/Sep/2023 17:25:21] "[35m[1mGET /tutores HTTP/1.1[0m" 500 - - call_trace=/Users/tairik/PycharmProjects/mvp-tairik/venv/lib/python3.9/site-packages/werkzeug/_internal.py L224 
[2023-09-06 17:26:31,393] INFO _log() L224   * Detected change in '/Users/tairik/PycharmProjects/mvp-tairik/rest_api_tutores/app.py', reloading - call_trace=/Users/tairik/PycharmProjects/mvp-tairik/venv/lib/python3.9/site-packages/werkzeug/_internal.py L224 
[2023-09-06 17:26:45,229] INFO _new_conn() L757  Starting new HTTPS connection (1): emailvalidation.abstractapi.com - call_trace=/Users/tairik/PycharmProjects/mvp-tairik/venv/lib/python3.9/site-packages/requests/packages/urllib3/connectionpool.py L757 
[2023-09-06 17:26:48,139] ERROR log_exception() L1449 Exception on /tutores [GET] - call_trace=/Users/tairik/PycharmProjects/mvp-tairik/venv/lib/python3.9/site-packages/flask/app.py L1449
Traceback (most recent call last):
  File "/Users/tairik/PycharmProjects/mvp-tairik/venv/lib/python3.9/site-packages/flask/app.py", line 2073, in wsgi_app
    response = self.full_dispatch_request()
  File "/Users/tairik/PycharmProjects/mvp-tairik/venv/lib/python3.9/site-packages/flask/app.py", line 1519, in full_dispatch_request
    rv = self.handle_user_exception(e)
  File "/Users/tairik/PycharmProjects/mvp-tairik/venv/lib/python3.9/site-packages/flask_cors/extension.py", line 165, in wrapped_function
    return cors_after_request(app.make_response(f(*args, **kwargs)))
  File "/Users/tairik/PycharmProjects/mvp-tairik/venv/lib/python3.9/site-packages/flask/app.py", line 1517, in full_dispatch_request
    rv = self.dispatch_request()
  File "/Users/tairik/PycharmProjects/mvp-tairik/venv/lib/python3.9/site-packages/flask/app.py", line 1503, in dispatch_request
    return self.ensure_sync(self.view_functions[rule.endpoint])(**req.view_args)
  File "/Users/tairik/PycharmProjects/mvp-tairik/venv/lib/python3.9/site-packages/flask_openapi3/scaffold.py", line 109, in wrapper
    resp = _do_wrapper(
  File "/Users/tairik/PycharmProjects/mvp-tairik/venv/lib/python3.9/site-packages/flask_openapi3/do_wrapper.py", line 135, in _do_wrapper
    response = func(**request_kwargs)
  File "/Users/tairik/PycharmProjects/mvp-tairik/rest_api_tutores/app.py", line 132, in get_tutores
    print(results.is_valid_format.value)
AttributeError: 'dict' object has no attribute 'is_valid_format'
[2023-09-06 17:26:48,158] INFO _log() L224  127.0.0.1 - - [06/Sep/2023 17:26:48] "[35m[1mGET /tutores HTTP/1.1[0m" 500 - - call_trace=/Users/tairik/PycharmProjects/mvp-tairik/venv/lib/python3.9/site-packages/werkzeug/_internal.py L224 
[2023-09-06 17:27:00,691] INFO _log() L224   * Detected change in '/Users/tairik/PycharmProjects/mvp-tairik/rest_api_tutores/app.py', reloading - call_trace=/Users/tairik/PycharmProjects/mvp-tairik/venv/lib/python3.9/site-packages/werkzeug/_internal.py L224 
[2023-09-06 17:27:02,695] INFO _new_conn() L757  Starting new HTTPS connection (1): emailvalidation.abstractapi.com - call_trace=/Users/tairik/PycharmProjects/mvp-tairik/venv/lib/python3.9/site-packages/requests/packages/urllib3/connectionpool.py L757 
[2023-09-06 17:27:03,503] INFO _log() L224  127.0.0.1 - - [06/Sep/2023 17:27:03] "GET /tutores HTTP/1.1" 200 - - call_trace=/Users/tairik/PycharmProjects/mvp-tairik/venv/lib/python3.9/site-packages/werkzeug/_internal.py L224 
[2023-09-06 17:27:45,612] INFO _log() L224   * Detected change in '/Users/tairik/PycharmProjects/mvp-tairik/rest_api_tutores/app.py', reloading - call_trace=/Users/tairik/PycharmProjects/mvp-tairik/venv/lib/python3.9/site-packages/werkzeug/_internal.py L224 
[2023-09-06 17:27:50,290] INFO _log() L224   * Detected change in '/Users/tairik/PycharmProjects/mvp-tairik/rest_api_tutores/app.py', reloading - call_trace=/Users/tairik/PycharmProjects/mvp-tairik/venv/lib/python3.9/site-packages/werkzeug/_internal.py L224 
[2023-09-06 17:27:54,156] INFO _new_conn() L757  Starting new HTTPS connection (1): emailvalidation.abstractapi.com - call_trace=/Users/tairik/PycharmProjects/mvp-tairik/venv/lib/python3.9/site-packages/requests/packages/urllib3/connectionpool.py L757 
[2023-09-06 17:27:55,183] INFO _log() L224  127.0.0.1 - - [06/Sep/2023 17:27:55] "GET /tutores HTTP/1.1" 200 - - call_trace=/Users/tairik/PycharmProjects/mvp-tairik/venv/lib/python3.9/site-packages/werkzeug/_internal.py L224 
[2023-09-06 17:28:05,036] INFO _log() L224   * Detected change in '/Users/tairik/PycharmProjects/mvp-tairik/rest_api_tutores/app.py', reloading - call_trace=/Users/tairik/PycharmProjects/mvp-tairik/venv/lib/python3.9/site-packages/werkzeug/_internal.py L224 
[2023-09-06 17:28:07,467] INFO _new_conn() L757  Starting new HTTPS connection (1): emailvalidation.abstractapi.com - call_trace=/Users/tairik/PycharmProjects/mvp-tairik/venv/lib/python3.9/site-packages/requests/packages/urllib3/connectionpool.py L757 
[2023-09-06 17:28:08,277] ERROR log_exception() L1449 Exception on /tutores [GET] - call_trace=/Users/tairik/PycharmProjects/mvp-tairik/venv/lib/python3.9/site-packages/flask/app.py L1449
Traceback (most recent call last):
  File "/Users/tairik/PycharmProjects/mvp-tairik/venv/lib/python3.9/site-packages/flask/app.py", line 2073, in wsgi_app
    response = self.full_dispatch_request()
  File "/Users/tairik/PycharmProjects/mvp-tairik/venv/lib/python3.9/site-packages/flask/app.py", line 1519, in full_dispatch_request
    rv = self.handle_user_exception(e)
  File "/Users/tairik/PycharmProjects/mvp-tairik/venv/lib/python3.9/site-packages/flask_cors/extension.py", line 165, in wrapped_function
    return cors_after_request(app.make_response(f(*args, **kwargs)))
  File "/Users/tairik/PycharmProjects/mvp-tairik/venv/lib/python3.9/site-packages/flask/app.py", line 1517, in full_dispatch_request
    rv = self.dispatch_request()
  File "/Users/tairik/PycharmProjects/mvp-tairik/venv/lib/python3.9/site-packages/flask/app.py", line 1503, in dispatch_request
    return self.ensure_sync(self.view_functions[rule.endpoint])(**req.view_args)
  File "/Users/tairik/PycharmProjects/mvp-tairik/venv/lib/python3.9/site-packages/flask_openapi3/scaffold.py", line 109, in wrapper
    resp = _do_wrapper(
  File "/Users/tairik/PycharmProjects/mvp-tairik/venv/lib/python3.9/site-packages/flask_openapi3/do_wrapper.py", line 135, in _do_wrapper
    response = func(**request_kwargs)
  File "/Users/tairik/PycharmProjects/mvp-tairik/rest_api_tutores/app.py", line 132, in get_tutores
    print(results["is_valid_format"].value)
AttributeError: 'dict' object has no attribute 'value'
[2023-09-06 17:28:08,290] INFO _log() L224  127.0.0.1 - - [06/Sep/2023 17:28:08] "[35m[1mGET /tutores HTTP/1.1[0m" 500 - - call_trace=/Users/tairik/PycharmProjects/mvp-tairik/venv/lib/python3.9/site-packages/werkzeug/_internal.py L224 
[2023-09-06 17:28:14,445] INFO _log() L224   * Detected change in '/Users/tairik/PycharmProjects/mvp-tairik/rest_api_tutores/app.py', reloading - call_trace=/Users/tairik/PycharmProjects/mvp-tairik/venv/lib/python3.9/site-packages/werkzeug/_internal.py L224 
